Workbook

Sheet HudoAddList -完成品
A1: 薬品名：
A2: 期間： | B2: 2025/ 5/ 1～2025/12/ 8
A3: 回転数： | B3: 0以下
A4: 薬価：
A5: 使用期限：
A6: 経過措置： | B6: なし
A7: 管理区分： | B7: すべて
A8: 余剰在庫金額： | B8: 416865円
A9: No. | B9: 管理区分 | C9: 薬品名 | D9: 剤区分 | E9: 薬価 | F9: 全在庫数 | G9: 回転数 | H9: 経過措置日 | I9: 使用期限 | J9: ロット番号 | K9: 在庫数量 | L9: 原価 | M9: 金額 | N9: 登録 | O9: 登録数 | P9: 備考 | Q9: あやめ | R9: ひまわり
A10: 1 | B10: 調剤 | C10: 「山善」第二リン灰 | E10: 1.58 | F10: 396 | G10: 0 | I10: 46143 | J10: A3F21 | K10: 396 | L10: 1.53 | M10: 606 | N10: 0 | Q10: =VLOOKUP(C10,あやめ!E:U,17,FALSE) -> #N/A | R10: =VLOOKUP(C10,ひまわり!E:U,17,FALSE) -> #N/A
A11: 2 | B11: 調剤 | C11: ０．０５％ヘキザック水Ｗ | E11: 0.68 | F11: 3000 | G11: 0 | I11: 46478 | J11: 524846 | K11: 1500 | L11: 0.53 | M11: 795 | N11: 0 | Q11: =VLOOKUP(C11,あやめ!E:U,17,FALSE) -> #N/A | R11: =VLOOKUP(C11,ひまわり!E:U,17,FALSE) -> #N/A
A12: 3 | B12: 調剤 | C12: ０．０５％ヘキザック水Ｗ | E12: 0.68 | F12: 3000 | G12: 0 | I12: 46508 | J12: 624025 | K12: 1500 | L12: 0.53 | M12: 795 | N12: 0 | Q12: =VLOOKUP(C12,あやめ!E:U,17,FALSE) -> #N/A | R12: =VLOOKUP(C12,ひまわり!E:U,17,FALSE) -> #N/A
A13: 4 | B13: 調剤 | C13: ０．５％ヘキザック水Ｗ | E13: 0.68 | F13: 1500 | G13: 0 | I13: 46569 | J13: 824423 | K13: 1500 | L13: 0.58 | M13: 870 | N13: 0 | Q13: =VLOOKUP(C13,あやめ!E:U,17,FALSE) -> #N/A | R13: =VLOOKUP(C13,ひまわり!E:U,17,FALSE) -> #N/A
A14: 5 | B14: 調剤 | C14: ５％ヒビテン液 | E14: 1.94 | F14: 1000 | G14: 0 | I14: 46569 | J14: 4175C | K14: 1000 | L14: 1.69 | M14: 1690 | N14: 0 | Q14: =VLOOKUP(C14,あやめ!E:U,17,FALSE) -> #N/A | R14: =VLOOKUP(C14,ひまわり!E:U,17,FALSE) -> #N/A
A15: 6 | B15: 調剤 | C15: アーテン錠（２ｍｇ） | E15: 9.1 | F15: 307 | G15: 0 | I15: 46266 | J15: LG0113 | K15: 200 | L15: 6.55 | M15: 1310 | N15: 0 | Q15: =VLOOKUP(C15,あやめ!E:U,17,FALSE) -> #N/A | R15: =VLOOKUP(C15,ひまわり!E:U,17,FALSE) -> 0
A16: 7 | B16: 調剤 | C16: アーテン錠（２ｍｇ） | E16: 9.1 | F16: 307 | G16: 0 | I16: 46266 | J16: LC2539 | K16: 100 | L16: 6.55 | M16: 655 | N16: 0 | Q16: =VLOOKUP(C16,あやめ!E:U,17,FALSE) -> #N/A | R16: =VLOOKUP(C16,ひまわり!E:U,17,FALSE) -> 0
A17: 8 | B17: 調剤 | C17: アーテン錠（２ｍｇ） | E17: 9.1 | F17: 307 | G17: 0 | I17: 46266 | J17: KA1140 | K17: 7 | L17: 6.55 | M17: 46 | N17: 0 | Q17: =VLOOKUP(C17,あやめ!E:U,17,FALSE) -> #N/A | R17: =VLOOKUP(C17,ひまわり!E:U,17,FALSE) -> 0
A18: 9 | B18: 調剤 | C18: アイドロイチン３％点眼液 ５ｍＬ | E18: 91.6 | F18: 5 | G18: 0 | H18: 46477 | I18: 46266 | J18: 3AD0234 | K18: 4 | L18: 68.4 | M18: 274 | N18: 0 | Q18: =VLOOKUP(C18,あやめ!E:U,17,FALSE) -> #N/A | R18: =VLOOKUP(C18,ひまわり!E:U,17,FALSE) -> #N/A
A19: 10 | B19: 調剤 | C19: アイドロイチン３％点眼液 ５ｍＬ | E19: 91.6 | F19: 5 | G19: 0 | H19: 46477 | K19: 1 | L19: 68.4 | M19: 68 | N19: 0 | Q19: =VLOOKUP(C19,あやめ!E:U,17,FALSE) -> #N/A | R19: =VLOOKUP(C19,ひまわり!E:U,17,FALSE) -> #N/A
A20: 11 | B20: 調剤 | C20: アクロマイシン軟膏３％ ３０ｍｇ | E20: 18.6 | F20: 10 | G20: 0 | I20: 46905 | J20: 2406007 | K20: 10 | L20: 14.6 | M20: 146 | N20: 0 | Q20: =VLOOKUP(C20,あやめ!E:U,17,FALSE) -> #N/A | R20: =VLOOKUP(C20,ひまわり!E:U,17,FALSE) -> #N/A
A21: 12 | B21: 調剤 | C21: アズノールＳＴ錠口腔用５ｍｇ | E21: 10.9 | F21: 1 | G21: 0 | K21: 1 | L21: 11.39 | M21: 11 | N21: 0 | O21: 1 | Q21: =VLOOKUP(C21,あやめ!E:U,17,FALSE) -> #N/A | R21: =VLOOKUP(C21,ひまわり!E:U,17,FALSE) -> 0
A22: 13 | B22: 調剤 | C22: アセトアミノフェン坐剤小児用２００ｍｇ「日新」 | E22: 20.9 | F22: 14 | G22: 0 | K22: 14 | L22: 18.45 | M22: 258 | N22: 0 | O22: 14 | Q22: =VLOOKUP(C22,あやめ!E:U,17,FALSE) -> #N/A | R22: =VLOOKUP(C22,ひまわり!E:U,17,FALSE) -> #N/A
A23: 14 | B23: 調剤 | C23: アセトアミノフェン錠２００ｍｇ「マルイシ」 | E23: 6.1 | F23: 2 | G23: 0 | I23: 46539 | J23: 4X1721 | K23: 2 | L23: 6.1 | M23: 12 | N23: 0 | Q23: =VLOOKUP(C23,あやめ!E:U,17,FALSE) -> 7747 | R23: =VLOOKUP(C23,ひまわり!E:U,17,FALSE) -> 2583
A24: 15 | B24: 調剤 | C24: アゼルニジピン錠１６ｍｇ「タナベ」 | E24: 12.2 | F24: 72 | G24: 0 | H24: 45565 | K24: 72 | L24: 9.39 | M24: 676 | N24: 0 | O24: 100 | Q24: =VLOOKUP(C24,あやめ!E:U,17,FALSE) -> #N/A | R24: =VLOOKUP(C24,ひまわり!E:U,17,FALSE) -> #N/A
A25: 16 | B25: 調剤 | C25: アトラント外用液１％ | E25: 24.3 | F25: 170 | G25: 0 | I25: 46357 | J25: 40101 | K25: 170 | L25: 21.18 | M25: 3601 | N25: 0 | Q25: =VLOOKUP(C25,あやめ!E:U,17,FALSE) -> #N/A | R25: =VLOOKUP(C25,ひまわり!E:U,17,FALSE) -> #N/A
A26: 17 | B26: 調剤 | C26: アドソルビン原末 | E26: 0.77 | F26: 4 | G26: 0 | H26: 46112 | K26: 4 | L26: 0.99 | M26: 4 | N26: 0 | O26: 4 | Q26: =VLOOKUP(C26,あやめ!E:U,17,FALSE) -> #N/A | R26: =VLOOKUP(C26,ひまわり!E:U,17,FALSE) -> #N/A
A27: 18 | B27: 調剤 | C27: アプレピタントカプセル８０ｍｇ「サワイ」 | E27: 636 | F27: 12 | G27: 0 | I27: 46082 | J27: X23501 | K27: 12 | L27: 643.17 | M27: 7718 | N27: 0 | Q27: =VLOOKUP(C27,あやめ!E:U,17,FALSE) -> 0 | R27: =VLOOKUP(C27,ひまわり!E:U,17,FALSE) -> #N/A
A28: 19 | B28: 調剤 | C28: アマンタジン塩酸塩錠５０ｍｇ「サワイ」 | E28: 6.1 | F28: 2 | G28: 0 | I28: 46661 | J28: 724902 | K28: 2 | L28: 6.1 | M28: 12 | N28: 0 | Q28: =VLOOKUP(C28,あやめ!E:U,17,FALSE) -> 540 | R28: =VLOOKUP(C28,ひまわり!E:U,17,FALSE) -> 168
A29: 20 | B29: 調剤 | C29: アムロジピン錠２．５ｍｇ「トーワ」 | D29: 劇薬 | E29: 10.4 | F29: 2 | G29: 0 | I29: 46966 | J29: D0179 | K29: 2 | L29: 10.4 | M29: 21 | N29: 0 | Q29: =VLOOKUP(C29,あやめ!E:U,17,FALSE) -> 7449 | R29: =VLOOKUP(C29,ひまわり!E:U,17,FALSE) -> #N/A
A30: 21 | B30: 調剤 | C30: アムロジピン錠５ｍｇ「日医工」 | D30: 劇薬 | E30: 10.4 | F30: 2 | G30: 0 | I30: 46753 | J30: K00200 | K30: 2 | L30: 8 | M30: 16 | N30: 0 | Q30: =VLOOKUP(C30,あやめ!E:U,17,FALSE) -> 9360 | R30: =VLOOKUP(C30,ひまわり!E:U,17,FALSE) -> 4862
A31: 22 | B31: 調剤 | C31: アルファカルシドール錠１．０μｇ「アメル」 １μｇ | D31: 劇薬 | E31: 6.1 | F31: 2 | G31: 0 | I31: 46753 | J31: 2505 | K31: 2 | L31: 6.1 | M31: 12 | N31: 0 | Q31: =VLOOKUP(C31,あやめ!E:U,17,FALSE) -> 5160 | R31: =VLOOKUP(C31,ひまわり!E:U,17,FALSE) -> #N/A
A32: 23 | B32: 調剤 | C32: アルプラゾラム錠０．４ｍｇ「サワイ」 | D32: 向3 | E32: 5.9 | F32: 2 | G32: 0 | I32: 46784 | J32: 524Z01 | K32: 2 | L32: 5.13 | M32: 10 | N32: 0 | Q32: =VLOOKUP(C32,あやめ!E:U,17,FALSE) -> 1006 | R32: =VLOOKUP(C32,ひまわり!E:U,17,FALSE) -> #N/A
A33: 24 | B33: 調剤 | C33: アレジオンＬＸ点眼液０．１％ | E33: 493 | F33: 20 | G33: 0 | I33: 46508 | J33: 1AE0258 | K33: 20 | L33: 438.82 | M33: 8776 | N33: 0 | Q33: =VLOOKUP(C33,あやめ!E:U,17,FALSE) -> 0 | R33: =VLOOKUP(C33,ひまわり!E:U,17,FALSE) -> 0
A34: 25 | B34: 調剤 | C34: アンブロキソール塩酸塩徐放カプセル４５ｍｇ「ＺＥ」 | E34: 16.1 | F34: 5 | G34: 0 | I34: 46327 | J34: 188J | K34: 5 | L34: 11.6 | M34: 58 | N34: 0 | Q34: =VLOOKUP(C34,あやめ!E:U,17,FALSE) -> #N/A | R34: =VLOOKUP(C34,ひまわり!E:U,17,FALSE) -> #N/A
A35: 26 | B35: 調剤 | C35: アンブロキソール塩酸塩錠１５ｍｇ「トーワ」 | E35: 5.9 | F35: 2 | G35: 0 | I35: 47027 | J35: A0487 | K35: 2 | L35: 5.26 | M35: 11 | N35: 0 | Q35: =VLOOKUP(C35,あやめ!E:U,17,FALSE) -> 10277 | R35: =VLOOKUP(C35,ひまわり!E:U,17,FALSE) -> #N/A
A36: 27 | B36: 調剤 | C36: イソジンゲル１０％ | E36: 4.22 | F36: 90 | G36: 0 | I36: 46478 | J36: GBE502 | K36: 90 | L36: 4.21 | M36: 379 | N36: 0 | Q36: =VLOOKUP(C36,あやめ!E:U,17,FALSE) -> #N/A | R36: =VLOOKUP(C36,ひまわり!E:U,17,FALSE) -> #N/A
A37: 28 | B37: 調剤 | C37: イドメシンコーワパップ７０ｍｇ １０ｃｍ×１４ｃｍ | E37: 17.1 | F37: 40 | G37: 0 | H37: 45747 | I37: 46357 | J37: UB001 | K37: 40 | L37: 17 | M37: 680 | N37: 0 | Q37: =VLOOKUP(C37,あやめ!E:U,17,FALSE) -> #N/A | R37: =VLOOKUP(C37,ひまわり!E:U,17,FALSE) -> 0
A38: 29 | B38: 調剤 | C38: イブプロフェン錠１００ｍｇ「ＮＩＧ」 | E38: 6.1 | F38: 2 | G38: 0 | I38: 46569 | J38: GR0789 | K38: 2 | L38: 6.1 | M38: 12 | N38: 0 | Q38: =VLOOKUP(C38,あやめ!E:U,17,FALSE) -> 2822 | R38: =VLOOKUP(C38,ひまわり!E:U,17,FALSE) -> 0
A39: 30 | B39: 調剤 | C39: イリボーＯＤ錠２．５μｇ | D39: 劇薬 | E39: 37.3 | F39: 95 | G39: 0 | I39: 46447 | J39: 24006R1 | K39: 95 | L39: 32.89 | M39: 3125 | N39: 0 | Q39: =VLOOKUP(C39,あやめ!E:U,17,FALSE) -> #N/A | R39: =VLOOKUP(C39,ひまわり!E:U,17,FALSE) -> #N/A
A40: 31 | B40: 調剤 | C40: エストラーナテープ０．７２ｍｇ ９ｃｍ２ | E40: 74.5 | F40: 2 | G40: 0 | K40: 2 | L40: 71.17 | M40: 142 | N40: 0 | Q40: =VLOOKUP(C40,あやめ!E:U,17,FALSE) -> #N/A | R40: =VLOOKUP(C40,ひまわり!E:U,17,FALSE) -> #N/A
...

Sheet ひまわり
A1: ブロック | B1: 選択なし
A2: 店舗 | B2: ひまわり薬局
A3: 薬品名 | C3: 部分一致
A4: メーカー名 | C4: 部分一致
A5: 非表示設定 | B5: 非表示以外
A6: 薬品区分 | B6: - すべて -
A7: 剤型 | B7: - すべて -
A8: 経過措置日 | B8: - すべて -
A9: 管理区分 | B9: - すべて -
A10: 集計期間 | B10: 2025年09月01日 ～ 2025年12月07日
A11: 在庫数量 | B11: すべて
A12: 算定時除外対象薬 | B12: すべて
A13: 後発品(GE) | B13: すべて
A14: ハイリスク薬 | B14: すべて
A15: 新薬創出・適応外薬解消等促進加算 | B15: すべて
A16: 管理薬剤 | B16: すべて
... A21: 不動在庫商品のみ | B21: すべて
A22: 出力日 | B22: 45999
A23: 後発品構成比 | B23: 0.9471 | C23: 後発品処方換算数量 | D23: 209648 | E23: 処方換算数量合計 | F23: 221352 | G23: 後発品構成比（臨時） | H23: 0.9521 | I23: 後発品処方換算数量（臨時） | J23: 179863 | K23: 処方換算数量合計（臨時） | L23: 188900
A24: No. | B24: 管理区分 | C24: レセ電コード | D24: メーカー | E24: 薬品名 | F24: 薬品区分 | G24: 剤型 | H24: GE | I24: ハイ | J24: 新創 | K24: 局方 | L24: 漢方 | M24: ｵｰﾌｧﾝ | N24: 除外 | O24: 薬価 | P24: 原価 | Q24: 単位 | R24: 在庫数量 | S24: 在庫金額 | T24: 回転数 | U24: 処方数量 | V24: 処方金額 | W24: 他出庫数量 | X24: 他出庫金額 | Y24: 入庫数量 | Z24: 入庫金額 | AA24: 経過措置日
A25: 1 | B25: 調剤 | C25: 622916901 | D25: ヤンセンファーマ | E25: ジスバルカプセル４０ｍｇ | F25: 劇薬 | G25: 内服 | N25: 除外 | O25: 2297.9 | P25: 2297.9 | Q25: カプセル | R25: 106 | S25: 243577 | T25: 3.31 | U25: 222 | V25: 510135 | Y25: 300 | Z25: 689370
A26: 2 | B26: 調剤 | C26: 622623101 | D26: アステラス製薬 | E26: イクスタンジ錠８０ｍｇ | F26: 劇薬 | G26: 内服 | I26: ハイ | N26: 除外 | O26: 4101.8 | P26: 4101.79 | Q26: 錠 | R26: 56 | S26: 229700 | T26: 1 | U26: 56 | V26: 229701 | Y26: 112 | Z26: 459400
A27: 3 | B27: 調剤 | C27: 622699301 | D27: 武田薬品 | E27: トリンテリックス錠１０ｍｇ | F27: 劇薬 | G27: 内服 | I27: ハイ | N27: 除外 | O27: 161.7 | P27: 161.7 | Q27: 錠 | R27: 1304.5 | S27: 210938 | T27: 5 | U27: 5318.5 | V27: 860004 | Y27: 5800 | Z27: 937860
A28: 4 | B28: 調剤 | C28: 622484701 | D28: エーザイ | E28: フィコンパ錠４ｍｇ | F28: 無し | G28: 内服 | I28: ハイ | J28: 新創 | N28: 除外 | O28: 319.7 | P28: 319.7 | Q28: 錠 | R28: 587 | S28: 187664 | T28: 0.96 | U28: 451 | V28: 144186 | Y28: 684 | Z28: 217140
A29: 5 | B29: 調剤 | C29: 622986601 | D29: ＭＳＤ | E29: ラゲブリオ錠４００ｍｇ | F29: 劇薬 | G29: 内服 | N29: 除外 | O29: 4329.8 | P29: 4329.8 | Q29: 錠 | R29: 40 | S29: 173192 | T29: 1 | U29: 40 | V29: 173192 | Y29: 80 | Z29: 346384
A30: 6 | B30: 調剤 | C30: 622833401 | D30: 大塚製薬 | E30: レキサルティＯＤ錠２ｍｇ | F30: 劇薬 | G30: 内服 | I30: ハイ | N30: 除外 | O30: 461.9 | P30: 461.9 | Q30: 錠 | R30: 329 | S30: 151965 | T30: 6 | U30: 2013 | V30: 929806 | Y30: 2000 | Z30: 923800
A31: 7 | B31: 調剤 | C31: 622068301 | D31: バイエル | E31: イグザレルト錠１０ｍｇ | F31: 無し | G31: 内服 | I31: ハイ | N31: 除外 | O31: 331.6 | P31: 331.6 | Q31: 錠 | R31: 371.5 | S31: 123189 | T31: 0.77 | U31: 306 | V31: 101467 | Y31: 255 | Z31: 50745
A32: 8 | B32: 調剤 | C32: 622819401 | D32: 協和キリン | E32: ダーブロック錠６ｍｇ | F32: 劇薬 | G32: 内服 | N32: 除外 | O32: 378.4 | P32: 378.4 | Q32: 錠 | R32: 313 | S32: 118439 | T32: 0.32 | U32: 105 | V32: 39732 | Y32: 69 | Z32: 692
A33: 9 | B33: 調剤 | C33: 622496901 | D33: ＭｅｉｊｉＳｅｉｋａ | E33: シクレスト舌下錠１０ｍｇ | F33: 劇薬 | G33: 内服 | I33: ハイ | N33: 除外 | O33: 307 | P33: 307 | Q33: 錠 | R33: 383 | S33: 117581 | T33: 0.45 | U33: 180 | V33: 55260 | Y33: 144 | Z33: 26640
A34: 10 | B34: 調剤 | C34: 622546701 | E34: インチュニブ錠１ｍｇ | F34: 劇薬 | G34: 内服 | I34: ハイ | N34: 除外 | O34: 398.8 | P34: 398.8 | Q34: 錠 | R34: 235 | S34: 93718 | T34: 4.43 | U34: 1149 | V34: 458222 | Y34: 1100 | Z34: 438680
A35: 11 | B35: 調剤 | C35: 622449601 | D35: ヴィアトリス | E35: イフェクサーＳＲカプセル７５ｍｇ | F35: 劇薬 | G35: 内服 | I35: ハイ | N35: 除外 | O35: 167.6 | P35: 167.6 | Q35: カプセル | R35: 559 | S35: 93688 | T35: 5.95 | U35: 2688 | V35: 450507 | Y35: 2902 | Z35: 486242
A36: 12 | B36: 調剤 | C36: 622994101 | D36: 第一三共 | E36: アビラテロン酢酸エステル錠２５０ｍｇ「ＤＳＥＰ」 | F36: 劇薬 | G36: 内服 | H36: GE | O36: 1632.3 | P36: 1632.3 | Q36: 錠 | R36: 56 | S36: 91409 | Y36: 56 | Z36: 91409
A37: 13 | B37: 調剤 | C37: 622573601 | D37: 第一三共 | E37: カナリア配合錠 | F37: 無し | G37: 内服 | I37: ハイ | N37: 除外 | O37: 208.5 | P37: 208.5 | Q37: 錠 | R37: 438 | S37: 91323 | T37: 5.34 | U37: 2285 | V37: 476426 | Y37: 2305 | Z37: 480180
A38: 14 | B38: 調剤 | C38: 622930901 | D38: 興和 | E38: アリドネパッチ５５ｍｇ | F38: 劇薬 | G38: 外用 | N38: 除外 | O38: 437.6 | P38: 437.57 | Q38: 枚 | R38: 203 | S38: 88827 | T38: 1.63 | U38: 271 | V38: 118590 | Y38: 344 | Z38: 136908
A39: 15 | B39: 調剤 | C39: 622342001 | D39: 小野薬品 | E39: フォシーガ錠１０ｍｇ | F39: 無し | G39: 内服 | I39: ハイ | J39: 新創 | N39: 除外 | O39: 220.3 | P39: 220.3 | Q39: 錠 | R39: 326.5 | S39: 71928 | T39: 0.3 | U39: 63 | V39: 13879 | Y39: 300 | Z39: 66090
A40: 16 | B40: 調剤 | C40: 622833301 | D40: 大塚製薬 | E40: レキサルティＯＤ錠１ｍｇ | F40: 劇薬 | G40: 内服 | I40: ハイ | N40: 除外 | O40: 241.8 | P40: 241.8 | Q40: 錠 | R40: 293 | S40: 70847 | T40: 5.57 | U40: 1582 | V40: 382524 | Y40: 1600 | Z40: 383253
A41: 17 | B41: 調剤 | C41: 622093301 | D41: アステラス製薬 | E41: ベタニス錠５０ｍｇ | F41: 劇薬 | G41: 内服 | N41: 除外 | O41: 141.7 | P41: 141.7 | Q41: 錠 | R41: 489 | S41: 69291 | T41: 4.25 | U41: 1930 | V41: 273483 | Y41: 2000 | Z41: 283400
A42: 18 | B42: 調剤 | C42: 622546801 | E42: インチュニブ錠３ｍｇ | F42: 劇薬 | G42: 内服 | I42: ハイ | N42: 除外 | O42: 527.2 | P42: 448.12 | Q42: 錠 | R42: 153 | S42: 68562 | T42: 3.21 | U42: 250 | V42: 131800 | Y42: 400 | Z42: 179248
A43: 19 | B43: 調剤 | C43: 622794801 | D43: 住友ファーマ | E43: ラツーダ錠４０ｍｇ | F43: 劇薬 | G43: 内服 | I43: ハイ | N43: 除外 | O43: 295.8 | P43: 295.8 | Q43: 錠 | R43: 230 | S43: 68034 | T43: 2.98 | U43: 729 | V43: 215638 | Y43: 700 | Z43: 207060
A44: 20 | B44: 調剤 | C44: 620007996 | D44: 日本新薬 | E44: エビプロスタット配合錠ＤＢ | F44: 無し | G44: 内服 | O44: 25.5 | P44: 25.5 | Q44: 錠 | R44: 2507 | S44: 63929 | T44: 4.17 | U44: 8322 | V44: 212213 | Y44: 9349 | Z44: 231258
...

Sheet あやめ
A1: ブロック | B1: 選択なし
A2: 店舗 | B2: あやめ薬局
A3: 薬品名 | C3: 部分一致
A4: メーカー名 | C4: 部分一致
A5: 非表示設定 | B5: 非表示以外
A6: 薬品区分 | B6: - すべて -
A7: 剤型 | B7: - すべて -
A8: 経過措置日 | B8: - すべて -
A9: 管理区分 | B9: - すべて -
A10: 集計期間 | B10: 2025年09月01日 ～ 2025年12月07日
A11: 在庫数量 | B11: すべて
A12: 算定時除外対象薬 | B12: すべて
A13: 後発品(GE) | B13: すべて
A14: ハイリスク薬 | B14: すべて
A15: 新薬創出・適応外薬解消等促進加算 | B15: すべて
A16: 管理薬剤 | B16: すべて
... A21: 不動在庫商品のみ | B21: すべて
A22: 出力日 | B22: 45999
A23: 後発品構成比 | B23: 0.9595 | C23: 後発品処方換算数量 | D23: 355525.3 | E23: 処方換算数量合計 | F23: 370530.1 | G23: 後発品構成比（臨時） | H23: 0.978 | I23: 後発品処方換算数量（臨時） | J23: 299419.8 | K23: 処方換算数量合計（臨時） | L23: 306124.6
A24: No. | B24: 管理区分 | C24: レセ電コード | D24: メーカー | E24: 薬品名 | F24: 薬品区分 | G24: 剤型 | H24: GE | I24: ハイ | J24: 新創 | K24: 局方 | L24: 漢方 | M24: ｵｰﾌｧﾝ | N24: 除外 | O24: 薬価 | P24: 原価 | Q24: 単位 | R24: 在庫数量 | S24: 在庫金額 | T24: 回転数 | U24: 処方数量 | V24: 処方金額 | W24: 他出庫数量 | X24: 他出庫金額 | Y24: 入庫数量 | Z24: 入庫金額 | AA24: 経過措置日
A25: 1 | B25: 調剤 | C25: 622622601 | D25: 塩野義 | E25: ゾフルーザ錠２０ｍｇ | F25: 無し | G25: 内服 | J25: 新創 | N25: 除外 | O25: 2438.8 | P25: 2438.8 | Q25: 錠 | R25: 139 | S25: 338993 | T25: 4.16 | U25: 389 | V25: 948696 | Y25: 480 | Z25: 1170624
A26: 2 | B26: 調剤 | C26: 622404401 | D26: 武田薬品 | E26: タケキャブ錠１０ｍｇ | F26: 無し | G26: 内服 | N26: 除外 | O26: 94.3 | P26: 94.3 | Q26: 錠 | R26: 1790 | S26: 168797 | T26: 6.55 | U26: 8811 | V26: 830873 | Y26: 9700 | Z26: 914710
A27: 3 | B27: 調剤 | C27: 622576101 | D27: 第一三共 | E27: リクシアナＯＤ錠３０ｍｇ | F27: 無し | G27: 内服 | I27: ハイ | J27: 新創 | N27: 除外 | O27: 411.3 | P27: 411.3 | Q27: 錠 | R27: 287 | S27: 118043 | T27: 3.45 | U27: 777 | V27: 319579 | Y27: 900 | Z27: 370170
A28: 4 | B28: 調剤 | C28: 628785801 | D28: 塩野義 | E28: ゾコーバ錠１２５ｍｇ | F28: 劇薬 | G28: 内服 | N28: 除外 | O28: 7090 | P28: 7090 | Q28: 錠 | R28: 14 | S28: 99260 | T28: 8.5 | U28: 238 | V28: 1687420 | Y28: 210 | Z28: 1488900
A29: 5 | B29: 調剤 | C29: 622225001 | E29: エリキュース錠５ｍｇ | F29: 無し | G29: 内服 | I29: ハイ | N29: 除外 | O29: 207 | P29: 207 | Q29: 錠 | R29: 322 | S29: 66654 | T29: 1.79 | U29: 376 | V29: 77832 | Y29: 600 | Z29: 124200
A30: 6 | B30: 調剤 | C30: 622696101 | D30: エーザイ | E30: エクフィナ錠５０ｍｇ | F30: 劇薬 | G30: 内服 | N30: 除外 | O30: 867.9 | P30: 867.9 | Q30: 錠 | R30: 74 | S30: 64225 | T30: 1.7 | U30: 126 | V30: 109356 | Y30: 200 | Z30: 173580
A31: 7 | B31: 調剤 | C31: 622306701 | D31: アステラス製薬 | E31: スーグラ錠５０ｍｇ | F31: 無し | G31: 内服 | I31: ハイ | J31: 新創 | N31: 除外 | O31: 149.7 | P31: 149.7 | Q31: 錠 | R31: 398 | S31: 59581 | T31: 4.05 | U31: 1590 | V31: 238023 | Y31: 1600 | Z31: 239520
A32: 8 | B32: 調剤 | C32: 622336801 | D32: 興和 | E32: デベルザ錠２０ｍｇ | F32: 無し | G32: 内服 | I32: ハイ | J32: 新創 | N32: 除外 | O32: 144.2 | P32: 144.2 | Q32: 錠 | R32: 407 | S32: 58689 | T32: 2.92 | U32: 908 | V32: 130934 | Y32: 1100 | Z32: 158620
A33: 9 | B33: 調剤 | C33: 622623101 | D33: アステラス製薬 | E33: イクスタンジ錠８０ｍｇ | F33: 劇薬 | G33: 内服 | I33: ハイ | N33: 除外 | O33: 4101.8 | P33: 4101.79 | Q33: 錠 | R33: 14 | S33: 57425 | T33: 16 | U33: 224 | V33: 918804 | Y33: 224 | Z33: 918800
A34: 10 | B34: 調剤 | C34: 622821101 | D34: ノバルティスＰ | E34: エンレスト錠２００ｍｇ | F34: 無し | G34: 内服 | N34: 除外 | O34: 188.2 | P34: 188.2 | Q34: 錠 | R34: 290 | S34: 54578 | T34: 2.41 | U34: 706 | V34: 132869 | Y34: 700 | Z34: 131740
A35: 11 | B35: 調剤 | C35: 622653001 | E35: ベオーバ錠５０ｍｇ | F35: 無し | G35: 内服 | N35: 除外 | O35: 146.1 | P35: 146.1 | Q35: 錠 | R35: 363 | S35: 53034 | T35: 2.75 | U35: 1003 | V35: 146539 | Y35: 1000 | Z35: 146100
A36: 12 | B36: 調剤 | C36: 622655001 | D36: 日本ベーリンガー | E36: トラディアンス配合錠ＡＰ | F36: 無し | G36: 内服 | I36: ハイ | N36: 除外 | O36: 235.8 | P36: 235.8 | Q36: 錠 | R36: 218 | S36: 51404 | T36: 2.78 | U36: 583 | V36: 137471 | Y36: 600 | Z36: 141480
A37: 13 | B37: 調剤 | C37: 622699001 | D37: 旭化成ファーマ | E37: テリボン皮下注２８．２μｇオートインジェクター | F37: 無し | G37: 注射 | N37: 除外 | O37: 5995 | P37: 5995 | Q37: キット | R37: 8 | S37: 47960 | T37: 5 | U37: 40 | V37: 239800 | Y37: 48 | Z37: 287760
A38: 14 | B38: 調剤 | C38: 622342001 | D38: 小野薬品 | E38: フォシーガ錠１０ｍｇ | F38: 無し | G38: 内服 | I38: ハイ | J38: 新創 | N38: 除外 | O38: 220.3 | P38: 220.3 | Q38: 錠 | R38: 216 | S38: 47585 | T38: 8.09 | U38: 1817 | V38: 400287 | Y38: 1800 | Z38: 396540
A39: 15 | B39: 調剤 | C39: 622576201 | D39: 第一三共 | E39: リクシアナＯＤ錠６０ｍｇ | F39: 無し | G39: 内服 | I39: ハイ | J39: 新創 | N39: 除外 | O39: 416.8 | P39: 416.8 | Q39: 錠 | R39: 113 | S39: 47098 | T39: 0.98 | U39: 120 | V39: 50016 | Y39: 100 | Z39: 41680
A40: 16 | B40: 調剤 | C40: 622930601 | D40: 久光製薬 | E40: アポハイドローション２０％ | F40: 無し | G40: 外用 | N40: 除外 | O40: 543.7 | P40: 543.7 | Q40: ｇ | R40: 86.4 | S40: 46976 | T40: 0.79 | U40: 56.16 | V40: 30535 | Y40: 86.4 | Z40: 46976
A41: 17 | B41: 調剤 | C41: 622336601 | D41: 第一三共 | E41: エフィエント錠３．７５ｍｇ | F41: 無し | G41: 内服 | I41: ハイ | N41: 除外 | O41: 248.8 | P41: 248.8 | Q41: 錠 | R41: 188 | S41: 46774 | T41: 3.09 | U41: 351 | V41: 87328 | Y41: 500 | Z41: 124400
A42: 18 | B42: 調剤 | C42: 622471601 | D42: 佐藤製薬 | E42: ルコナック爪外用液５％ | F42: 無し | G42: 外用 | N42: 除外 | O42: 663.6 | P42: 663.6 | Q42: ｇ | R42: 70 | S42: 46452 | T42: 0.82 | U42: 49 | V42: 32515 | Y42: 70 | Z42: 46452
A43: 19 | B43: 調剤 | C43: 621729704 | D43: 武田薬品 | E43: ｄ－クロルフェニラミンマレイン酸塩錠２ｍｇ「ＮＩＧ」 | F43: 無し | G43: 内服 | H43: GE | O43: 5.9 | P43: 5.9 | Q43: 錠 | R43: 7812 | S43: 46091 | T43: 1.47 | U43: 7328 | V43: 43234 | Y43: 13000 | Z43: 76700
A44: 20 | B44: 調剤 | C44: 622401201 | D44: 日本ベーリンガー | E44: ジャディアンス錠１０ｍｇ | F44: 無し | G44: 内服 | I44: ハイ | J44: 新創 | N44: 除外 | O44: 166 | P44: 166 | Q44: 錠 | R44: 258 | S44: 42828 | T44: 2.34 | U44: 571 | V44: 94786 | Y44: 600 | Z44: 99600
...
